String value is: <?xml version="1.0" ?> <!-- =================================================================================== --> <!-- |    This document was autogenerated by xacro from /home/luis/workshop_ws/install/controlko_description/share/controlko_description/urdf/rrbot.urdf.xacro | --> <!-- |    EDITING THIS FILE BY HAND IS NOT RECOMMENDED                                 | --> <!-- =================================================================================== --> <robot name="rrbot"> <material name="StoglRobotics/Violet"> <color rgba="0.4 0.1803921568627451 0.5686274509803921 1.0"/> <ambient>1 0 0 1</ambient> <diffuse>1 0 0 1</diffuse> <specular>0.1 0.1 0.1 1</specular> <emissive>0 0 0 0</emissive> </material> <material name="StoglRobotics/DarkGrey"> <color rgba="0.2 0.2 0.2 1.0"/> <ambient>1 0 0 1</ambient> <diffuse>1 0 0 1</diffuse> <specular>0.1 0.1 0.1 1</specular> <emissive>0 0 0 0</emissive> </material> <material name="StoglRobotics/LightGrey"> <color rgba="0.7607843137254902 0.7607843137254902 0.7607843137254902 1.0"/> <ambient>1 0 0 1</ambient> <diffuse>1 0 0 1</diffuse> <specular>0.1 0.1 0.1 1</specular> <emissive>0 0 0 0</emissive> </material> <!-- create link fixed to the "world" --> <link name="world"/> <!-- LINKS --> <!-- base link --> <link name="base_link"> <inertial> <origin rpy="0 0 0" xyz="0 0 0"/> <mass value="0.01"/> <inertia ixx="0.001" ixy="0.0" ixz="0.0" iyy="0.001" iyz="0.0" izz="0.001"/> </inertial> <visual> <origin rpy="0 0 0" xyz="0 0 0.15"/> <geometry> <box size="0.3 0.3 0.3"/> </geometry> <material name="StoglRobotics/Violet"/> </visual> <collision> <origin rpy="0 0 0" xyz="0 0 0.15"/> <geometry> <box size="0.3 0.3 0.3"/> </geometry> </collision> </link> <gazebo reference="base_link"> <material>Gazebo/Orange</material> </gazebo> <!-- link 1 --> <link name="link1"> <inertial> <origin rpy="0 0 0" xyz="0 0 0"/> <mass value="0.01"/> <inertia ixx="0.001" ixy="0.0" ixz="0.0" iyy="0.001" iyz="0.0" izz="0.001"/> </inertial> <visual> <origin rpy="0 0 0" xyz="0 0 0.25"/> <geometry> <cylinder length="0.5" radius="0.1"/> </geometry> <material name="StoglRobotics/DarkGrey"/> </visual> <collision> <origin rpy="0 0 0" xyz="0 0 0.25"/> <geometry> <cylinder length="0.5" radius="0.1"/> </geometry> </collision> </link> <gazebo reference="link1"> <material>Gazebo/Black</material> </gazebo> <!-- link 2 --> <link name="link2"> <inertial> <origin rpy="0 0 0" xyz="0 0 0"/> <mass value="0.01"/> <inertia ixx="0.001" ixy="0.0" ixz="0.0" iyy="0.001" iyz="0.0" izz="0.001"/> </inertial> <visual> <origin rpy="0 0 0" xyz="0 0 0.3"/> <geometry> <box size="0.1 0.1 0.6"/> </geometry> <material name="StoglRobotics/LightGrey"/> </visual> <collision> <origin rpy="0 0 0" xyz="0 0 0.3"/> <geometry> <box size="0.1 0.1 0.6"/> </geometry> </collision> </link> <gazebo reference="link2"> <material>Gazebo/Gray</material> </gazebo> <!-- All-zero tool frame. This frame should correspond to the TOOL frame of the robot's controller.) --> <link name="tool0"/> <!-- tool link --> <!-- START Delete if not needed --> <!-- Standard frames for industrial robots. Also useful for manipulators. (ROS-I specs - https://wiki.ros.org/Industrial/Tutorials/WorkingWithRosIndustrialRobotSupportPackages#Standardised_links_.2F_frames)--> <!-- This frame should correspond to the BASE coordinate system of robot's controller.) --> <link name="base"/> <!-- Frame for mounting EEF models to a manipulator. x+ axis points forward (REP 103). --> <link name="flange"/> <!-- END Delete if not needed  --> <!-- END LINKS --> <!-- JOINTS --> <!-- base_joint fixes base_link to the environment --> <joint name="base_joint" type="fixed"> <origin rpy="0 0 0" xyz="0 0 0"/> <parent link="world"/> <child link="base_link"/> </joint> <!-- joint 1 --> <joint name="joint1" type="revolute"> <origin rpy="0 0 0" xyz="0 0 0.3"/> <parent link="base_link"/> <child link="link1"/> <axis xyz="0 0 1"/> <limit effort="1000" lower="-6.632251157578453" upper="6.632251157578453" velocity="3.141592653589793"/> </joint> <!-- joint 2 --> <joint name="joint2" type="revolute"> <origin rpy="0 -1.5707963267948966 0" xyz="0 0 0.5"/> <parent link="link1"/> <child link="link2"/> <axis xyz="0 1 0"/> <limit effort="1000" lower="-1.0471975511965976" upper="4.1887902047863905" velocity="3.141592653589793"/> </joint> <!-- tool frame - fixed frame --> <joint name="link2-tool0" type="fixed"> <parent link="link2"/> <child link="tool0"/> <origin rpy="0 -3.141592653589793 -1.5707963267948966" xyz="0 0 0.6"/> </joint> <!-- END JOINTS --> <!-- START Delete if not needed --> <!-- Standard frames for industrial robots. Also useful for manipulators. (ROS-I specs - https://wiki.ros.org/Industrial/Tutorials/WorkingWithRosIndustrialRobotSupportPackages#Standardised_links_.2F_frames)--> <joint name="base_link-base_joint" type="fixed"> <origin rpy="0 0 0" xyz="0 0 0"/> <parent link="base_link"/> <child link="base"/> </joint> <joint name="tool0-flange_joint" type="fixed"> <origin rpy="0 0 0" xyz="0 0 0"/> <parent link="tool0"/> <child link="flange"/> </joint> <!-- END Delete if not needed  --> <ros2_control name="rrbot" type="system"> <hardware> <plugin>my_hardware_interface/RRBotHardwareInterface</plugin> <param name="can_device_count">1</param> <plugin>my_hardware_interface/RRBotHardwareInterface</plugin> </hardware> <joint name="friction_wheel1_joint"> <command_interface name="velocity"> <param name="initial_value">0.0</param> </command_interface> <state_interface name="velocity"> <param name="initial_value">0.0</param> </state_interface> <state_interface name="position"> <param name="initial_value">0.0</param> </state_interface> <param name="initial_value">0.0</param> <param name="can_bus">can0</param> <param name="tx_id">1</param> <param name="offset">0</param> <param name="motor_type">M3508</param> </joint> <joint name="friction_wheel2_joint"> <command_interface name="velocity"> <param name="initial_value">0.0</param> </command_interface> <state_interface name="velocity"> <param name="initial_value">0.0</param> </state_interface> <state_interface name="position"> <param name="initial_value">0.0</param> </state_interface> <param name="initial_value">0.0</param> <param name="can_bus">can0</param> <param name="tx_id">2</param> <param name="offset">0</param> <param name="motor_type">M3508</param> </joint> <joint name="friction_wheel3_joint"> <command_interface name="velocity"> <param name="initial_value">0.0</param> </command_interface> <state_interface name="velocity"> <param name="initial_value">0.0</param> </state_interface> <state_interface name="position"> <param name="initial_value">0.0</param> </state_interface> <param name="initial_value">0.0</param> <param name="can_bus">can0</param> <param name="tx_id">3</param> <param name="offset">0</param> <param name="motor_type">M3508</param> </joint> <joint name="friction_wheel4_joint"> <command_interface name="velocity"> <param name="initial_value">0.0</param> </command_interface> <state_interface name="velocity"> <param name="initial_value">0.0</param> </state_interface> <state_interface name="position"> <param name="initial_value">0.0</param> </state_interface> <param name="initial_value">0.0</param> <param name="can_bus">can0</param> <param name="tx_id">4</param> <param name="offset">0</param> <param name="motor_type">M3508</param> </joint> <!-- <joint name="friction_wheel2_joint"> <command_interface name="position"/> <state_interface name="position"> <param name="initial_value">0.0</param> </state_interface> </joint> --> <!-- <joint name="${prefix}friction_wheel1_joint"> <param name="can_bus">can0</param> <param name="tx_id">1</param> <param name="offset">0</param> <param name="motor_type">M3508</param>
<command_interface name="velocity"></command_interface>
<state_interface name="position"/> <state_interface name="velocity"/> </joint> --> </ros2_control> </robot>
